Workbook

Sheet RAW_DATA
A1: Record ID | B1: Category | C1: Student Name | D1: Course / Interest | E1: State / Country | F1: Counsellor Name | G1: Lead Status | H1: Chat/Call Status | I1: Lead Source
A2: 1 | B2: General | C2: Neha Singh | D2: General Education Counselling | E2: Rajasthan | F2: Rahul | G2: New | H2: Fee details shared | I2: WhatsApp
A3: 2 | B3: General | C3: Rajitha | D3: General Education Counselling | E3: West Bengal | F3: Anjali | G3: Follow-up | H3: Interested in admission | I3: Facebook
A4: 3 | B4: General | C4: GUNJA MUKUNDA | D4: General Education Counselling | E4: Telangana | F4: Rahul | G4: Not Interested | H4: Asked for college options | I4: Instagram
A5: 4 | B5: General | C5: Sai Charan. AR | D5: General Education Counselling | E5: Karnataka | F5: Rahul | G5: Pending | H5: Wrong/unclear requirement | I5: Referral
A6: 5 | B6: General | C6: Krishna A | D6: General Education Counselling | E6: Odisha | F6: Rahul | G6: New | H6: Call back tomorrow | I6: Website
A7: 6 | B7: General | C7: BUVAN.G | D7: General Education Counselling | E7: Andhra Pradesh | F7: Anjali | G7: Follow-up | H7: Asked for college options | I7: WhatsApp
A8: 7 | B8: General | C8: Pheba Xavier | D8: General Education Counselling | E8: Kerala | F8: Priya | G8: New | H8: Asked for college options | I8: Facebook
A9: 8 | B9: General | C9: Sasik | D9: General Education Counselling | E9: Delhi | F9: Anjali | G9: Not Interested | H9: Asked for college options | I9: Instagram
A10: 9 | B10: General | C10: Hdhdbhd | D10: General Education Counselling | E10: Maharashtra | F10: Arun | G10: Follow-up | H10: Interested - follow up | I10: Referral
A11: 10 | B11: General | C11: Boitumelo | D11: Bed Foundation | E11: Tamil Nadu | F11: Priya | G11: Follow-up | H11: Requested course details | I11: Website
A12: 11 | B12: General | C12: Chaitra | D12: General Education Counselling | E12: Rajasthan | F12: Anjali | G12: Not Interested | H12: Wrong/unclear requirement | I12: WhatsApp
A13: 12 | B13: General | C13: Binita nisika | D13: General Education Counselling | E13: West Bengal | F13: Sneha | G13: Follow-up | H13: Interested in admission | I13: Facebook
... A67: 66 | B67: General | C67: Hafsah Khanum | D67: Interior Design | E67: Andhra Pradesh | F67: Priya | G67: Follow-up | H67: Fee details shared | I67: WhatsApp

Sheet CLEAN_DATA
A1: Record ID | B1: Category | C1: Student Name | D1: Course / Interest | E1: State / Country | F1: Counsellor Name | G1: Lead Status | H1: Chat/Call Status | I1: Lead Source | J1: Review Required | K1: Review Reason | L1: Duplicate Status | M1: Follow-up Required
A2: 1 | B2: General | C2: Neha Singh | D2: General Education Counselling | E2: Rajasthan | F2: Rahul | G2: New | H2: Fee details shared | I2: WhatsApp | J2: No | L2: =IF(J2="Yes","Review",IF(COUNTIF($C$2:$C$67,C2)>1,"Duplicate","Unique")) -> Duplicate | M2: =IF(OR(G2="Follow-up",H2="Call back tomorrow",H2="Interested - follow up"),"Yes","No") -> No | O2: Total Duplicate | P2: =COUNTIF(L2:L67,"Duplicate") -> 30
A3: 2 | B3: General | C3: Rajitha | D3: General Education Counselling | E3: West Bengal | F3: Anjali | G3: Follow-up | H3: Interested in admission | I3: Facebook | J3: No | L3: =IF(J3="Yes","Review",IF(COUNTIF($C$2:$C$67,C3)>1,"Duplicate","Unique")) -> Unique | M3: =IF(OR(G3="Follow-up",H3="Call back tomorrow",H3="Interested - follow up"),"Yes","No") -> Yes
A4: 3 | B4: General | C4: GUNJA MUKUNDA | D4: General Education Counselling | E4: Telangana | F4: Rahul | G4: Not Interested | H4: Asked for college options | I4: Instagram | J4: No | L4: =IF(J4="Yes","Review",IF(COUNTIF($C$2:$C$67,C4)>1,"Duplicate","Unique")) -> Duplicate | M4: =IF(OR(G4="Follow-up",H4="Call back tomorrow",H4="Interested - follow up"),"Yes","No") -> No
A5: 4 | B5: General | C5: Sai Charan. AR | D5: General Education Counselling | E5: Karnataka | F5: Rahul | G5: Pending | H5: Wrong/unclear requirement | I5: Referral | J5: No | L5: =IF(J5="Yes","Review",IF(COUNTIF($C$2:$C$67,C5)>1,"Duplicate","Unique")) -> Duplicate | M5: =IF(OR(G5="Follow-up",H5="Call back tomorrow",H5="Interested - follow up"),"Yes","No") -> No
A6: 5 | B6: General | C6: Krishna A | D6: General Education Counselling | E6: Odisha | F6: Rahul | G6: New | H6: Call back tomorrow | I6: Website | J6: No | L6: =IF(J6="Yes","Review",IF(COUNTIF($C$2:$C$67,C6)>1,"Duplicate","Unique")) -> Duplicate | M6: =IF(OR(G6="Follow-up",H6="Call back tomorrow",H6="Interested - follow up"),"Yes","No") -> Yes
A7: 6 | B7: General | C7: BUVAN.G | D7: General Education Counselling | E7: Andhra Pradesh | F7: Anjali | G7: Follow-up | H7: Asked for college options | I7: WhatsApp | J7: No | L7: =IF(J7="Yes","Review",IF(COUNTIF($C$2:$C$67,C7)>1,"Duplicate","Unique")) -> Duplicate | M7: =IF(OR(G7="Follow-up",H7="Call back tomorrow",H7="Interested - follow up"),"Yes","No") -> Yes
A8: 7 | B8: General | C8: Pheba Xavier | D8: General Education Counselling | E8: Kerala | F8: Priya | G8: New | H8: Asked for college options | I8: Facebook | J8: No | L8: =IF(J8="Yes","Review",IF(COUNTIF($C$2:$C$67,C8)>1,"Duplicate","Unique")) -> Duplicate | M8: =IF(OR(G8="Follow-up",H8="Call back tomorrow",H8="Interested - follow up"),"Yes","No") -> No
A9: 8 | B9: General | C9: Sasik | D9: General Education Counselling | E9: Delhi | F9: Anjali | G9: Not Interested | H9: Asked for college options | I9: Instagram | J9: NO | L9: =IF(J9="Yes","Review",IF(COUNTIF($C$2:$C$67,C9)>1,"Duplicate","Unique")) -> Unique | M9: =IF(OR(G9="Follow-up",H9="Call back tomorrow",H9="Interested - follow up"),"Yes","No") -> No
A10: 9 | B10: General | C10: Hdhdbhd | D10: General Education Counselling | E10: Maharashtra | F10: Arun | G10: Follow-up | H10: Interested - follow up | I10: Referral | J10: YES | K10: Suspicious/gibberish name | L10: =IF(J10="Yes","Review",IF(COUNTIF($C$2:$C$67,C10)>1,"Duplicate","Unique")) -> Review | M10: =IF(OR(G10="Follow-up",H10="Call back tomorrow",H10="Interested - follow up"),"Yes","No") -> Yes
A11: 10 | B11: General | C11: Boitumelo | D11: Bed Foundation | E11: Tamil Nadu | F11: Priya | G11: Follow-up | H11: Requested course details | I11: Website | J11: No | L11: =IF(J11="Yes","Review",IF(COUNTIF($C$2:$C$67,C11)>1,"Duplicate","Unique")) -> Unique | M11: =IF(OR(G11="Follow-up",H11="Call back tomorrow",H11="Interested - follow up"),"Yes","No") -> Yes
A12: 11 | B12: General | C12: Chaitra | D12: General Education Counselling | E12: Rajasthan | F12: Anjali | G12: Not Interested | H12: Wrong/unclear requirement | I12: WhatsApp | J12: No | L12: =IF(J12="Yes","Review",IF(COUNTIF($C$2:$C$67,C12)>1,"Duplicate","Unique")) -> Unique | M12: =IF(OR(G12="Follow-up",H12="Call back tomorrow",H12="Interested - follow up"),"Yes","No") -> No
A13: 12 | B13: General | C13: Binita nisika | D13: General Education Counselling | E13: West Bengal | F13: Sneha | G13: Follow-up | H13: Interested in admission | I13: Facebook | J13: No | L13: =IF(J13="Yes","Review",IF(COUNTIF($C$2:$C$67,C13)>1,"Duplicate","Unique")) -> Unique | M13: =IF(OR(G13="Follow-up",H13="Call back tomorrow",H13="Interested - follow up"),"Yes","No") -> Yes
A14: 13 | B14: General | C14: Ankush | D14: Bachelor of Public Health | E14: Telangana | F14: Anjali | G14: New | H14: Not reachable | I14: Instagram | J14: No | L14: =IF(J14="Yes","Review",IF(COUNTIF($C$2:$C$67,C14)>1,"Duplicate","Unique")) -> Unique | M14: =IF(OR(G14="Follow-up",H14="Call back tomorrow",H14="Interested - follow up"),"Yes","No") -> No
A15: 14 | B15: General | C15: Md ahil raza | D15: School Education | E15: Karnataka | F15: Rahul | G15: New | H15: Wrong/unclear requirement | I15: Referral | J15: No | L15: =IF(J15="Yes","Review",IF(COUNTIF($C$2:$C$67,C15)>1,"Duplicate","Unique")) -> Unique | M15: =IF(OR(G15="Follow-up",H15="Call back tomorrow",H15="Interested - follow up"),"Yes","No") -> No
A16: 15 | B16: General | C16: Imsunepla | D16: General Education Counselling | E16: Odisha | F16: Rahul | G16: Follow-up | H16: Not reachable | I16: Website | J16: No | L16: =IF(J16="Yes","Review",IF(COUNTIF($C$2:$C$67,C16)>1,"Duplicate","Unique")) -> Unique | M16: =IF(OR(G16="Follow-up",H16="Call back tomorrow",H16="Interested - follow up"),"Yes","No") -> Yes
A17: 16 | B17: General | C17: Lakshmi P N | D17: General Education Counselling | E17: Andhra Pradesh | F17: Priya | G17: Follow-up | H17: Requested course details | I17: WhatsApp | J17: No | L17: =IF(J17="Yes","Review",IF(COUNTIF($C$2:$C$67,C17)>1,"Duplicate","Unique")) -> Unique | M17: =IF(OR(G17="Follow-up",H17="Call back tomorrow",H17="Interested - follow up"),"Yes","No") -> Yes
A18: 17 | B18: General | C18: lakshika tomer | D18: Intellectual Property Rights | E18: Kerala | F18: Arun | G18: Pending | H18: Call back tomorrow | I18: Facebook | J18: No | L18: =IF(J18="Yes","Review",IF(COUNTIF($C$2:$C$67,C18)>1,"Duplicate","Unique")) -> Unique | M18: =IF(OR(G18="Follow-up",H18="Call back tomorrow",H18="Interested - follow up"),"Yes","No") -> Yes
A19: 18 | B19: General | C19: roopa | D19: General Education Counselling | E19: Delhi | F19: Arun | G19: New | H19: Asked for college options | I19: Instagram | J19: No | L19: =IF(J19="Yes","Review",IF(COUNTIF($C$2:$C$67,C19)>1,"Duplicate","Unique")) -> Unique | M19: =IF(OR(G19="Follow-up",H19="Call back tomorrow",H19="Interested - follow up"),"Yes","No") -> No
A20: 19 | B20: General | C20: Deepak reddy mr | D20: Science / PCMB | E20: Maharashtra | F20: Sneha | G20: New | H20: Need eligibility check | I20: Referral | J20: No | L20: =IF(J20="Yes","Review",IF(COUNTIF($C$2:$C$67,C20)>1,"Duplicate","Unique")) -> Unique | M20: =IF(OR(G20="Follow-up",H20="Call back tomorrow",H20="Interested - follow up"),"Yes","No") -> No
A21: 20 | B21: General | C21: Sanjaykumar Somnath Dole | D21: Sanitary Inspector | E21: Tamil Nadu | F21: Sneha | G21: Pending | H21: Application initiated | I21: Website | J21: No | L21: =IF(J21="Yes","Review",IF(COUNTIF($C$2:$C$67,C21)>1,"Duplicate","Unique")) -> Unique | M21: =IF(OR(G21="Follow-up",H21="Call back tomorrow",H21="Interested - follow up"),"Yes","No") -> No
A22: 21 | B22: General | C22: Anonymous | D22: General Education Counselling | E22: Rajasthan | F22: Rahul | G22: New | H22: Application initiated | I22: WhatsApp | J22: Yes | K22: Placeholder/anonymous name | L22: =IF(J22="Yes","Review",IF(COUNTIF($C$2:$C$67,C22)>1,"Duplicate","Unique")) -> Review | M22: =IF(OR(G22="Follow-up",H22="Call back tomorrow",H22="Interested - follow up"),"Yes","No") -> No
A23: 22 | B23: General | C23: NAGARATHAN M N | D23: General Education Counselling | E23: West Bengal | F23: Sneha | G23: New | H23: Application initiated | I23: Facebook | J23: No | L23: =IF(J23="Yes","Review",IF(COUNTIF($C$2:$C$67,C23)>1,"Duplicate","Unique")) -> Unique | M23: =IF(OR(G23="Follow-up",H23="Call back tomorrow",H23="Interested - follow up"),"Yes","No") -> No
A24: 23 | B24: General | C24: Aadesh.R | D24: Bachelor of Business Administration | E24: Telangana | F24: Rahul | G24: Converted | H24: Fee details shared | I24: Instagram | J24: No | L24: =IF(J24="Yes","Review",IF(COUNTIF($C$2:$C$67,C24)>1,"Duplicate","Unique")) -> Unique | M24: =IF(OR(G24="Follow-up",H24="Call back tomorrow",H24="Interested - follow up"),"Yes","No") -> No
A25: 24 | B25: General | C25: Mounika Upparapalli | D25: General Education Counselling | E25: Karnataka | F25: Arun | G25: Not Interested | H25: Not reachable | I25: Referral | J25: No | L25: =IF(J25="Yes","Review",IF(COUNTIF($C$2:$C$67,C25)>1,"Duplicate","Unique")) -> Duplicate | M25: =IF(OR(G25="Follow-up",H25="Call back tomorrow",H25="Interested - follow up"),"Yes","No") -> No
A26: 25 | B26: General | C26: Junuthula vinaykumar | D26: General Education Counselling | E26: Odisha | F26: Anjali | G26: Follow-up | H26: Not reachable | I26: Website | J26: No | L26: =IF(J26="Yes","Review",IF(COUNTIF($C$2:$C$67,C26)>1,"Duplicate","Unique")) -> Unique | M26: =IF(OR(G26="Follow-up",H26="Call back tomorrow",H26="Interested - follow up"),"Yes","No") -> Yes
A27: 26 | B27: General | C27: Ashok Kumar Maharana | D27: General Education Counselling | E27: Andhra Pradesh | F27: Anjali | G27: Not Interested | H27: Fee details shared | I27: WhatsApp | J27: No | L27: =IF(J27="Yes","Review",IF(COUNTIF($C$2:$C$67,C27)>1,"Duplicate","Unique")) -> Unique | M27: =IF(OR(G27="Follow-up",H27="Call back tomorrow",H27="Interested - follow up"),"Yes","No") -> No
A28: 27 | B28: General | C28: Neha Singh | D28: General Education Counselling | E28: Kerala | F28: Rahul | G28: Pending | H28: Interested in admission | I28: Facebook | J28: No | L28: =IF(J28="Yes","Review",IF(COUNTIF($C$2:$C$67,C28)>1,"Duplicate","Unique")) -> Duplicate | M28: =IF(OR(G28="Follow-up",H28="Call back tomorrow",H28="Interested - follow up"),"Yes","No") -> No
A29: 28 | B29: General | C29: GUNJA MUKUNDA | D29: General Education Counselling | E29: Delhi | F29: Priya | G29: Not Interested | H29: Application initiated | I29: Instagram | J29: No | L29: =IF(J29="Yes","Review",IF(COUNTIF($C$2:$C$67,C29)>1,"Duplicate","Unique")) -> Duplicate | M29: =IF(OR(G29="Follow-up",H29="Call back tomorrow",H29="Interested - follow up"),"Yes","No") -> No
A30: 29 | B30: General | C30: Sai Charan. AR | D30: General Education Counselling | E30: Maharashtra | F30: Anjali | G30: Converted | H30: Wrong/unclear requirement | I30: Referral | J30: No | L30: =IF(J30="Yes","Review",IF(COUNTIF($C$2:$C$67,C30)>1,"Duplicate","Unique")) -> Duplicate | M30: =IF(OR(G30="Follow-up",H30="Call back tomorrow",H30="Interested - follow up"),"Yes","No") -> No
A31: 30 | B31: General | C31: Krishna A | D31: General Education Counselling | E31: Tamil Nadu | F31: Sneha | G31: Not Interested | H31: Asked for college options | I31: Website | J31: No | L31: =IF(J31="Yes","Review",IF(COUNTIF($C$2:$C$67,C31)>1,"Duplicate","Unique")) -> Duplicate | M31: =IF(OR(G31="Follow-up",H31="Call back tomorrow",H31="Interested - follow up"),"Yes","No") -> No
A32: 31 | B32: General | C32: BUVAN.G | D32: General Education Counselling | E32: Rajasthan | F32: Anjali | G32: Not Interested | H32: Not reachable | I32: WhatsApp | J32: No | L32: =IF(J32="Yes","Review",IF(COUNTIF($C$2:$C$67,C32)>1,"Duplicate","Unique")) -> Duplicate | M32: =IF(OR(G32="Follow-up",H32="Call back tomorrow",H32="Interested - follow up"),"Yes","No") -> No
A33: 32 | B33: General | C33: Pheba Xavier | D33: General Education Counselling | E33: West Bengal | F33: Rahul | G33: Follow-up | H33: Requested course details | I33: Facebook | J33: No | L33: =IF(J33="Yes","Review",IF(COUNTIF($C$2:$C$67,C33)>1,"Duplicate","Unique")) -> Duplicate | M33: =IF(OR(G33="Follow-up",H33="Call back tomorrow",H33="Interested - follow up"),"Yes","No") -> Yes
A34: 33 | B34: General | C34: Test | D34: General Education Counselling | E34: Telangana | F34: Sneha | G34: Converted | H34: Fee details shared | I34: Instagram | J34: Yes | K34: Test/placeholder record | L34: =IF(J34="Yes","Review",IF(COUNTIF($C$2:$C$67,C34)>1,"Duplicate","Unique")) -> Review | M34: =IF(OR(G34="Follow-up",H34="Call back tomorrow",H34="Interested - follow up"),"Yes","No") -> No
A35: 34 | B35: General | C35: sdfgsdfg | D35: General Education Counselling | E35: Karnataka | F35: Rahul | G35: Follow-up | H35: Need eligibility check | I35: Referral | J35: Yes | K35: Suspicious/gibberish name | L35: =IF(J35="Yes","Review",IF(COUNTIF($C$2:$C$67,C35)>1,"Duplicate","Unique")) -> Review | M35: =IF(OR(G35="Follow-up",H35="Call back tomorrow",H35="Interested - follow up"),"Yes","No") -> Yes
A36: 35 | B36: General | C36: Mounika Upparapalli | D36: General Education Counselling | E36: Odisha | F36: Sneha | G36: Follow-up | H36: Interested - follow up | I36: Website | J36: No | L36: =IF(J36="Yes","Review",IF(COUNTIF($C$2:$C$67,C36)>1,"Duplicate","Unique")) -> Duplicate | M36: =IF(OR(G36="Follow-up",H36="Call back tomorrow",H36="Interested - follow up"),"Yes","No") -> Yes
A37: 36 | B37: Fashion Design | C37: S Jenitha | D37: Fashion Communication | E37: Andhra Pradesh | F37: Arun | G37: Not Interested | H37: Interested - follow up | I37: WhatsApp | J37: No | L37: =IF(J37="Yes","Review",IF(COUNTIF($C$2:$C$67,C37)>1,"Duplicate","Unique")) -> Unique | M37: =IF(OR(G37="Follow-up",H37="Call back tomorrow",H37="Interested - follow up"),"Yes","No") -> Yes
A38: 37 | B38: Fashion Design | C38: Chandrashekhar v | D38: Fashion Design | E38: Kerala | F38: Anjali | G38: Follow-up | H38: Interested in admission | I38: Facebook | J38: No | L38: =IF(J38="Yes","Review",IF(COUNTIF($C$2:$C$67,C38)>1,"Duplicate","Unique")) -> Unique | M38: =IF(OR(G38="Follow-up",H38="Call back tomorrow",H38="Interested - follow up"),"Yes","No") -> Yes
A39: 38 | B39: Fashion Design | C39: Zoya mariyam | D39: Fashion Design | E39: Delhi | F39: Anjali | G39: Not Interested | H39: Asked for college options | I39: Instagram | J39: No | L39: =IF(J39="Yes","Review",IF(COUNTIF($C$2:$C$67,C39)>1,"Duplicate","Unique")) -> Duplicate | M39: =IF(OR(G39="Follow-up",H39="Call back tomorrow",H39="Interested - follow up"),"Yes","No") -> No
A40: 39 | B40: Fashion Design | C40: Janani Janani | D40: Fashion Design | E40: Maharashtra | F40: Priya | G40: Follow-up | H40: Need eligibility check | I40: Referral | J40: No | L40: =IF(J40="Yes","Review",IF(COUNTIF($C$2:$C$67,C40)>1,"Duplicate","Unique")) -> Unique | M40: =IF(OR(G40="Follow-up",H40="Call back tomorrow",H40="Interested - follow up"),"Yes","No") -> Yes
...

Sheet Counsellor Analysis
A1: Counsellor | B1: Total Leads | C1: New | D1: Follow-up | E1: Pending | F1: Converted | G1: Not Interested | H1: Conversion Rate
A2: Rahul | B2: =COUNTIF(CLEAN_DATA!$F$2:$F$67,A2) -> 15 | C2: =COUNTIFS(CLEAN_DATA!$F$2:$F$67,A2,CLEAN_DATA!$G$2:$G$67,C$1) -> 5 | D2: =COUNTIFS(CLEAN_DATA!$F$2:$F$67,A2,CLEAN_DATA!$G$2:$G$67,D$1) -> 4 | E2: =COUNTIFS(CLEAN_DATA!$F$2:$F$67,A2,CLEAN_DATA!$G$2:$G$67,E$1) -> 3 | F2: =COUNTIFS(CLEAN_DATA!$F$2:$F$67,A2,CLEAN_DATA!$G$2:$G$67,F$1) -> 1 | G2: =COUNTIFS(CLEAN_DATA!$F$2:$F$67,A2,CLEAN_DATA!$G$2:$G$67,G$1) -> 2 | H2: =F2/B2 -> 0.066666667
A3: Anjali | B3: =COUNTIF(CLEAN_DATA!$F$2:$F$67,A3) -> 16 | C3: =COUNTIFS(CLEAN_DATA!$F$2:$F$67,A3,CLEAN_DATA!$G$2:$G$67,C$1) -> 2 | D3: =COUNTIFS(CLEAN_DATA!$F$2:$F$67,A3,CLEAN_DATA!$G$2:$G$67,D$1) -> 5 | E3: =COUNTIFS(CLEAN_DATA!$F$2:$F$67,A3,CLEAN_DATA!$G$2:$G$67,E$1) -> 0 | F3: =COUNTIFS(CLEAN_DATA!$F$2:$F$67,A3,CLEAN_DATA!$G$2:$G$67,F$1) -> 2 | G3: =COUNTIFS(CLEAN_DATA!$F$2:$F$67,A3,CLEAN_DATA!$G$2:$G$67,G$1) -> 7 | H3: =F3/B3 -> 0.125
A4: Priya | B4: =COUNTIF(CLEAN_DATA!$F$2:$F$67,A4) -> 13 | C4: =COUNTIFS(CLEAN_DATA!$F$2:$F$67,A4,CLEAN_DATA!$G$2:$G$67,C$1) -> 6 | D4: =COUNTIFS(CLEAN_DATA!$F$2:$F$67,A4,CLEAN_DATA!$G$2:$G$67,D$1) -> 4 | E4: =COUNTIFS(CLEAN_DATA!$F$2:$F$67,A4,CLEAN_DATA!$G$2:$G$67,E$1) -> 1 | F4: =COUNTIFS(CLEAN_DATA!$F$2:$F$67,A4,CLEAN_DATA!$G$2:$G$67,F$1) -> 1 | G4: =COUNTIFS(CLEAN_DATA!$F$2:$F$67,A4,CLEAN_DATA!$G$2:$G$67,G$1) -> 1 | H4: =F4/B4 -> 0.076923077
A5: Arun | B5: =COUNTIF(CLEAN_DATA!$F$2:$F$67,A5) -> 11 | C5: =COUNTIFS(CLEAN_DATA!$F$2:$F$67,A5,CLEAN_DATA!$G$2:$G$67,C$1) -> 3 | D5: =COUNTIFS(CLEAN_DATA!$F$2:$F$67,A5,CLEAN_DATA!$G$2:$G$67,D$1) -> 1 | E5: =COUNTIFS(CLEAN_DATA!$F$2:$F$67,A5,CLEAN_DATA!$G$2:$G$67,E$1) -> 4 | F5: =COUNTIFS(CLEAN_DATA!$F$2:$F$67,A5,CLEAN_DATA!$G$2:$G$67,F$1) -> 1 | G5: =COUNTIFS(CLEAN_DATA!$F$2:$F$67,A5,CLEAN_DATA!$G$2:$G$67,G$1) -> 2 | H5: =F5/B5 -> 0.090909091
A6: Sneha | B6: =COUNTIF(CLEAN_DATA!$F$2:$F$67,A6) -> 11 | C6: =COUNTIFS(CLEAN_DATA!$F$2:$F$67,A6,CLEAN_DATA!$G$2:$G$67,C$1) -> 4 | D6: =COUNTIFS(CLEAN_DATA!$F$2:$F$67,A6,CLEAN_DATA!$G$2:$G$67,D$1) -> 3 | E6: =COUNTIFS(CLEAN_DATA!$F$2:$F$67,A6,CLEAN_DATA!$G$2:$G$67,E$1) -> 2 | F6: =COUNTIFS(CLEAN_DATA!$F$2:$F$67,A6,CLEAN_DATA!$G$2:$G$67,F$1) -> 1 | G6: =COUNTIFS(CLEAN_DATA!$F$2:$F$67,A6,CLEAN_DATA!$G$2:$G$67,G$1) -> 1 | H6: =F6/B6 -> 0.090909091
A7: Total | B7: =SUBTOTAL(109,Table5[Total Leads]) -> 66 | C7: =SUBTOTAL(109,Table5[New]) -> 20 | D7: =SUBTOTAL(109,Table5[Follow-up]) -> 17 | E7: =SUBTOTAL(109,Table5[Pending]) -> 10 | F7: =SUBTOTAL(109,Table5[Converted]) -> 6 | G7: =SUBTOTAL(109,Table5[Not Interested]) -> 13 | H7: =F7/B7 -> 0.090909091
B10: Best-Performing Counsellor | D10: =INDEX(A2:A6,MATCH(MAX(H2:H6),H2:H6,0)) -> Anjali

Sheet Chat_Call Analysis
A1: Chat/Call Status | B1: Total Leads | C1: New | D1: Follow-up | E1: Pending | F1: Converted | G1: Not Interested
A2: Fee details shared | B2: =COUNTIF(CLEAN_DATA!$H$2:$H$67,A2) -> 8 | C2: =COUNTIFS(CLEAN_DATA!$H$2:$H$67,$A2,CLEAN_DATA!$G$2:$G$67,C$1) -> 3 | D2: =COUNTIFS(CLEAN_DATA!$H$2:$H$67,$A2,CLEAN_DATA!$G$2:$G$67,D$1) -> 1 | E2: =COUNTIFS(CLEAN_DATA!$H$2:$H$67,$A2,CLEAN_DATA!$G$2:$G$67,E$1) -> 1 | F2: =COUNTIFS(CLEAN_DATA!$H$2:$H$67,$A2,CLEAN_DATA!$G$2:$G$67,F$1) -> 2 | G2: =COUNTIFS(CLEAN_DATA!$H$2:$H$67,$A2,CLEAN_DATA!$G$2:$G$67,G$1) -> 1
A3: Interested in admission | B3: =COUNTIF(CLEAN_DATA!$H$2:$H$67,A3) -> 9 | C3: =COUNTIFS(CLEAN_DATA!$H$2:$H$67,$A3,CLEAN_DATA!$G$2:$G$67,C$1) -> 1 | D3: =COUNTIFS(CLEAN_DATA!$H$2:$H$67,$A3,CLEAN_DATA!$G$2:$G$67,D$1) -> 5 | E3: =COUNTIFS(CLEAN_DATA!$H$2:$H$67,$A3,CLEAN_DATA!$G$2:$G$67,E$1) -> 2 | F3: =COUNTIFS(CLEAN_DATA!$H$2:$H$67,$A3,CLEAN_DATA!$G$2:$G$67,F$1) -> 0 | G3: =COUNTIFS(CLEAN_DATA!$H$2:$H$67,$A3,CLEAN_DATA!$G$2:$G$67,G$1) -> 1
A4: Asked for college options | B4: =COUNTIF(CLEAN_DATA!$H$2:$H$67,A4) -> 9 | C4: =COUNTIFS(CLEAN_DATA!$H$2:$H$67,$A4,CLEAN_DATA!$G$2:$G$67,C$1) -> 3 | D4: =COUNTIFS(CLEAN_DATA!$H$2:$H$67,$A4,CLEAN_DATA!$G$2:$G$67,D$1) -> 1 | E4: =COUNTIFS(CLEAN_DATA!$H$2:$H$67,$A4,CLEAN_DATA!$G$2:$G$67,E$1) -> 0 | F4: =COUNTIFS(CLEAN_DATA!$H$2:$H$67,$A4,CLEAN_DATA!$G$2:$G$67,F$1) -> 0 | G4: =COUNTIFS(CLEAN_DATA!$H$2:$H$67,$A4,CLEAN_DATA!$G$2:$G$67,G$1) -> 5
A5: Wrong/unclear requirement | B5: =COUNTIF(CLEAN_DATA!$H$2:$H$67,A5) -> 6 | C5: =COUNTIFS(CLEAN_DATA!$H$2:$H$67,$A5,CLEAN_DATA!$G$2:$G$67,C$1) -> 1 | D5: =COUNTIFS(CLEAN_DATA!$H$2:$H$67,$A5,CLEAN_DATA!$G$2:$G$67,D$1) -> 1 | E5: =COUNTIFS(CLEAN_DATA!$H$2:$H$67,$A5,CLEAN_DATA!$G$2:$G$67,E$1) -> 2 | F5: =COUNTIFS(CLEAN_DATA!$H$2:$H$67,$A5,CLEAN_DATA!$G$2:$G$67,F$1) -> 1 | G5: =COUNTIFS(CLEAN_DATA!$H$2:$H$67,$A5,CLEAN_DATA!$G$2:$G$67,G$1) -> 1
A6: Call back tomorrow | B6: =COUNTIF(CLEAN_DATA!$H$2:$H$67,A6) -> 8 | C6: =COUNTIFS(CLEAN_DATA!$H$2:$H$67,$A6,CLEAN_DATA!$G$2:$G$67,C$1) -> 5 | D6: =COUNTIFS(CLEAN_DATA!$H$2:$H$67,$A6,CLEAN_DATA!$G$2:$G$67,D$1) -> 0 | E6: =COUNTIFS(CLEAN_DATA!$H$2:$H$67,$A6,CLEAN_DATA!$G$2:$G$67,E$1) -> 2 | F6: =COUNTIFS(CLEAN_DATA!$H$2:$H$67,$A6,CLEAN_DATA!$G$2:$G$67,F$1) -> 1 | G6: =COUNTIFS(CLEAN_DATA!$H$2:$H$67,$A6,CLEAN_DATA!$G$2:$G$67,G$1) -> 0
A7: Interested - follow up | B7: =COUNTIF(CLEAN_DATA!$H$2:$H$67,A7) -> 4 | C7: =COUNTIFS(CLEAN_DATA!$H$2:$H$67,$A7,CLEAN_DATA!$G$2:$G$67,C$1) -> 0 | D7: =COUNTIFS(CLEAN_DATA!$H$2:$H$67,$A7,CLEAN_DATA!$G$2:$G$67,D$1) -> 2 | E7: =COUNTIFS(CLEAN_DATA!$H$2:$H$67,$A7,CLEAN_DATA!$G$2:$G$67,E$1) -> 0 | F7: =COUNTIFS(CLEAN_DATA!$H$2:$H$67,$A7,CLEAN_DATA!$G$2:$G$67,F$1) -> 0 | G7: =COUNTIFS(CLEAN_DATA!$H$2:$H$67,$A7,CLEAN_DATA!$G$2:$G$67,G$1) -> 2
A8: Requested course details | B8: =COUNTIF(CLEAN_DATA!$H$2:$H$67,A8) -> 5 | C8: =COUNTIFS(CLEAN_DATA!$H$2:$H$67,$A8,CLEAN_DATA!$G$2:$G$67,C$1) -> 1 | D8: =COUNTIFS(CLEAN_DATA!$H$2:$H$67,$A8,CLEAN_DATA!$G$2:$G$67,D$1) -> 3 | E8: =COUNTIFS(CLEAN_DATA!$H$2:$H$67,$A8,CLEAN_DATA!$G$2:$G$67,E$1) -> 0 | F8: =COUNTIFS(CLEAN_DATA!$H$2:$H$67,$A8,CLEAN_DATA!$G$2:$G$67,F$1) -> 1 | G8: =COUNTIFS(CLEAN_DATA!$H$2:$H$67,$A8,CLEAN_DATA!$G$2:$G$67,G$1) -> 0
A9: Not reachable | B9: =COUNTIF(CLEAN_DATA!$H$2:$H$67,A9) -> 7 | C9: =COUNTIFS(CLEAN_DATA!$H$2:$H$67,$A9,CLEAN_DATA!$G$2:$G$67,C$1) -> 2 | D9: =COUNTIFS(CLEAN_DATA!$H$2:$H$67,$A9,CLEAN_DATA!$G$2:$G$67,D$1) -> 2 | E9: =COUNTIFS(CLEAN_DATA!$H$2:$H$67,$A9,CLEAN_DATA!$G$2:$G$67,E$1) -> 1 | F9: =COUNTIFS(CLEAN_DATA!$H$2:$H$67,$A9,CLEAN_DATA!$G$2:$G$67,F$1) -> 0 | G9: =COUNTIFS(CLEAN_DATA!$H$2:$H$67,$A9,CLEAN_DATA!$G$2:$G$67,G$1) -> 2
A10: Need eligibility check | B10: =COUNTIF(CLEAN_DATA!$H$2:$H$67,A10) -> 4 | C10: =COUNTIFS(CLEAN_DATA!$H$2:$H$67,$A10,CLEAN_DATA!$G$2:$G$67,C$1) -> 1 | D10: =COUNTIFS(CLEAN_DATA!$H$2:$H$67,$A10,CLEAN_DATA!$G$2:$G$67,D$1) -> 2 | E10: =COUNTIFS(CLEAN_DATA!$H$2:$H$67,$A10,CLEAN_DATA!$G$2:$G$67,E$1) -> 0 | F10: =COUNTIFS(CLEAN_DATA!$H$2:$H$67,$A10,CLEAN_DATA!$G$2:$G$67,F$1) -> 1 | G10: =COUNTIFS(CLEAN_DATA!$H$2:$H$67,$A10,CLEAN_DATA!$G$2:$G$67,G$1) -> 0
A11: Application initiated | B11: =COUNTIF(CLEAN_DATA!$H$2:$H$67,A11) -> 6 | C11: =COUNTIFS(CLEAN_DATA!$H$2:$H$67,$A11,CLEAN_DATA!$G$2:$G$67,C$1) -> 3 | D11: =COUNTIFS(CLEAN_DATA!$H$2:$H$67,$A11,CLEAN_DATA!$G$2:$G$67,D$1) -> 0 | E11: =COUNTIFS(CLEAN_DATA!$H$2:$H$67,$A11,CLEAN_DATA!$G$2:$G$67,E$1) -> 2 | F11: =COUNTIFS(CLEAN_DATA!$H$2:$H$67,$A11,CLEAN_DATA!$G$2:$G$67,F$1) -> 0 | G11: =COUNTIFS(CLEAN_DATA!$H$2:$H$67,$A11,CLEAN_DATA!$G$2:$G$67,G$1) -> 1
A12: Total | B12: =SUBTOTAL(109,Table2[Total Leads]) -> 66 | C12: =SUBTOTAL(109,Table2[New]) -> 20 | D12: =SUBTOTAL(109,Table2[Follow-up]) -> 17 | E12: =SUBTOTAL(109,Table2[Pending]) -> 10 | F12: =SUBTOTAL(109,Table2[Converted]) -> 6 | G12: =SUBTOTAL(109,Table2[Not Interested]) -> 13

Sheet Conversion Analysis
A1: Metric | B1: Value | E1: Counsellor | F1: Total Leads | G1: Converted Leads | H1: Conversion Rate
A2: Total Leads | B2: =COUNTA(CLEAN_DATA!$A$2:$A$67) -> 66 | E2: Rahul | F2: =COUNTIF(CLEAN_DATA!$F$2:$F$67,E2) -> 15 | G2: =COUNTIFS(CLEAN_DATA!$F$2:$F$67,E2,CLEAN_DATA!$G$2:$G$67,"Converted") -> 1 | H2: =G2/F2 -> 0.066666667
A3: Converted Leads | B3: =COUNTIF(CLEAN_DATA!$G$2:$G$67,"Converted") -> 6 | E3: Anjali | F3: =COUNTIF(CLEAN_DATA!$F$2:$F$67,E3) -> 16 | G3: =COUNTIFS(CLEAN_DATA!$F$2:$F$67,E3,CLEAN_DATA!$G$2:$G$67,"Converted") -> 2 | H3: =G3/F3 -> 0.125
A4: Overall Conversion Rate | B4: =B3/B2 -> 0.090909091 | E4: Priya | F4: =COUNTIF(CLEAN_DATA!$F$2:$F$67,E4) -> 13 | G4: =COUNTIFS(CLEAN_DATA!$F$2:$F$67,E4,CLEAN_DATA!$G$2:$G$67,"Converted") -> 1 | H4: =G4/F4 -> 0.076923077
E5: Arun | F5: =COUNTIF(CLEAN_DATA!$F$2:$F$67,E5) -> 11 | G5: =COUNTIFS(CLEAN_DATA!$F$2:$F$67,E5,CLEAN_DATA!$G$2:$G$67,"Converted") -> 1 | H5: =G5/F5 -> 0.090909091
E6: Sneha | F6: =COUNTIF(CLEAN_DATA!$F$2:$F$67,E6) -> 11 | G6: =COUNTIFS(CLEAN_DATA!$F$2:$F$67,E6,CLEAN_DATA!$G$2:$G$67,"Converted") -> 1 | H6: =G6/F6 -> 0.090909091
A7: Conversion by Course | E7: Total | F7: =SUBTOTAL(109,Table6[Total Leads]) -> 66 | G7: =SUBTOTAL(109,Table6[Converted Leads]) -> 6 | H7: =G7/F7 -> 0.090909091
A9: Course | B9: Total Leads | C9: Converted Leads | D9: Conversion Rate | F9: Lead Source | G9: Total Leads | H9: Converted Leads | I9: Conversion Rate
A10: General Education Counselling | B10: =COUNTIF(CLEAN_DATA!$D$2:$D$67,A10) -> 29 | C10: =COUNTIFS(CLEAN_DATA!$D$2:$D$67,A10,CLEAN_DATA!$G$2:$G$67,"Converted") -> 2 | D10: =C10/B10 -> 0.068965517 | F10: WhatsApp | G10: =COUNTIF(CLEAN_DATA!$I$2:$I$67,F10) -> 14 | H10: =COUNTIFS(CLEAN_DATA!$I$2:$I$67,F10,CLEAN_DATA!$G$2:$G$67,"Converted") -> 1 | I10: =H10/G10 -> 0.071428571
A11: Bed Foundation | B11: =COUNTIF(CLEAN_DATA!$D$2:$D$67,A11) -> 1 | C11: =COUNTIFS(CLEAN_DATA!$D$2:$D$67,A11,CLEAN_DATA!$G$2:$G$67,"Converted") -> 0 | D11: =C11/B11 -> 0 | F11: Facebook | G11: =COUNTIF(CLEAN_DATA!$I$2:$I$67,F11) -> 13 | H11: =COUNTIFS(CLEAN_DATA!$I$2:$I$67,F11,CLEAN_DATA!$G$2:$G$67,"Converted") -> 2 | I11: =H11/G11 -> 0.15384615
A12: Bachelor of Public Health | B12: =COUNTIF(CLEAN_DATA!$D$2:$D$67,A12) -> 1 | C12: =COUNTIFS(CLEAN_DATA!$D$2:$D$67,A12,CLEAN_DATA!$G$2:$G$67,"Converted") -> 0 | D12: =C12/B12 -> 0 | F12: Instagram | G12: =COUNTIF(CLEAN_DATA!$I$2:$I$67,F12) -> 13 | H12: =COUNTIFS(CLEAN_DATA!$I$2:$I$67,F12,CLEAN_DATA!$G$2:$G$67,"Converted") -> 2 | I12: =H12/G12 -> 0.15384615
A13: School Education | B13: =COUNTIF(CLEAN_DATA!$D$2:$D$67,A13) -> 1 | C13: =COUNTIFS(CLEAN_DATA!$D$2:$D$67,A13,CLEAN_DATA!$G$2:$G$67,"Converted") -> 0 | D13: =C13/B13 -> 0 | F13: Referral | G13: =COUNTIF(CLEAN_DATA!$I$2:$I$67,F13) -> 13 | H13: =COUNTIFS(CLEAN_DATA!$I$2:$I$67,F13,CLEAN_DATA!$G$2:$G$67,"Converted") -> 1 | I13: =H13/G13 -> 0.076923077
A14: Intellectual Property Rights | B14: =COUNTIF(CLEAN_DATA!$D$2:$D$67,A14) -> 1 | C14: =COUNTIFS(CLEAN_DATA!$D$2:$D$67,A14,CLEAN_DATA!$G$2:$G$67,"Converted") -> 0 | D14: =C14/B14 -> 0 | F14: Website | G14: =COUNTIF(CLEAN_DATA!$I$2:$I$67,F14) -> 13 | H14: =COUNTIFS(CLEAN_DATA!$I$2:$I$67,F14,CLEAN_DATA!$G$2:$G$67,"Converted") -> 0 | I14: =H14/G14 -> 0
A15: Science / PCMB | B15: =COUNTIF(CLEAN_DATA!$D$2:$D$67,A15) -> 1 | C15: =COUNTIFS(CLEAN_DATA!$D$2:$D$67,A15,CLEAN_DATA!$G$2:$G$67,"Converted") -> 0 | D15: =C15/B15 -> 0 | F15: Total | G15: =SUBTOTAL(109,Table9[Total Leads]) -> 66 | H15: =SUBTOTAL(109,Table9[Converted Leads]) -> 6 | I15: =H15/G15 -> 0.090909091
A16: Sanitary Inspector | B16: =COUNTIF(CLEAN_DATA!$D$2:$D$67,A16) -> 1 | C16: =COUNTIFS(CLEAN_DATA!$D$2:$D$67,A16,CLEAN_DATA!$G$2:$G$67,"Converted") -> 0 | D16: =C16/B16 -> 0
A17: Bachelor of Business Administration | B17: =COUNTIF(CLEAN_DATA!$D$2:$D$67,A17) -> 1 | C17: =COUNTIFS(CLEAN_DATA!$D$2:$D$67,A17,CLEAN_DATA!$G$2:$G$67,"Converted") -> 1 | D17: =C17/B17 -> 1
A18: Fashion Communication | B18: =COUNTIF(CLEAN_DATA!$D$2:$D$67,A18) -> 1 | C18: =COUNTIFS(CLEAN_DATA!$D$2:$D$67,A18,CLEAN_DATA!$G$2:$G$67,"Converted") -> 0 | D18: =C18/B18 -> 0
A19: Fashion Design | B19: =COUNTIF(CLEAN_DATA!$D$2:$D$67,A19) -> 4 | C19: =COUNTIFS(CLEAN_DATA!$D$2:$D$67,A19,CLEAN_DATA!$G$2:$G$67,"Converted") -> 0 | D19: =C19/B19 -> 0
A20: Bachelor of Design | B20: =COUNTIF(CLEAN_DATA!$D$2:$D$67,A20) -> 3 | C20: =COUNTIFS(CLEAN_DATA!$D$2:$D$67,A20,CLEAN_DATA!$G$2:$G$67,"Converted") -> 0 | D20: =C20/B20 -> 0
A21: B.Des Animation Film Design | B21: =COUNTIF(CLEAN_DATA!$D$2:$D$67,A21) -> 1 | C21: =COUNTIFS(CLEAN_DATA!$D$2:$D$67,A21,CLEAN_DATA!$G$2:$G$67,"Converted") -> 1 | D21: =C21/B21 -> 1
A22: B.Des Game Design | B22: =COUNTIF(CLEAN_DATA!$D$2:$D$67,A22) -> 2 | C22: =COUNTIFS(CLEAN_DATA!$D$2:$D$67,A22,CLEAN_DATA!$G$2:$G$67,"Converted") -> 1 | D22: =C22/B22 -> 0.5
A23: Interior Design | B23: =COUNTIF(CLEAN_DATA!$D$2:$D$67,A23) -> 2 | C23: =COUNTIFS(CLEAN_DATA!$D$2:$D$67,A23,CLEAN_DATA!$G$2:$G$67,"Converted") -> 0 | D23: =C23/B23 -> 0
A24: Bachelor of Hospital Administration | B24: =COUNTIF(CLEAN_DATA!$D$2:$D$67,A24) -> 7 | C24: =COUNTIFS(CLEAN_DATA!$D$2:$D$67,A24,CLEAN_DATA!$G$2:$G$67,"Converted") -> 1 | D24: =C24/B24 -> 0.14285714
A25: Animation & VFX | B25: =COUNTIF(CLEAN_DATA!$D$2:$D$67,A25) -> 1 | C25: =COUNTIFS(CLEAN_DATA!$D$2:$D$67,A25,CLEAN_DATA!$G$2:$G$67,"Converted") -> 0 | D25: =C25/B25 -> 0
A26: Bachelor of Visual Arts | B26: =COUNTIF(CLEAN_DATA!$D$2:$D$67,A26) -> 2 | C26: =COUNTIFS(CLEAN_DATA!$D$2:$D$67,A26,CLEAN_DATA!$G$2:$G$67,"Converted") -> 0 | D26: =C26/B26 -> 0
A27: Bachelor of Architecture | B27: =COUNTIF(CLEAN_DATA!$D$2:$D$67,A27) -> 4 | C27: =COUNTIFS(CLEAN_DATA!$D$2:$D$67,A27,CLEAN_DATA!$G$2:$G$67,"Converted") -> 0 | D27: =C27/B27 -> 0
... A29: Bachelor of Hotel Management / Culinary Arts | B29: =COUNTIF(CLEAN_DATA!$D$2:$D$67,A29) -> 1 | C29: =COUNTIFS(CLEAN_DATA!$D$2:$D$67,A29,CLEAN_DATA!$G$2:$G$67,"Converted") -> 0 | D29: =C29/B29 -> 0
A30: Total | B30: =SUBTOTAL(109,Table8[Total Leads]) -> 66 | C30: =SUBTOTAL(109,Table8[Converted Leads]) -> 6 | D30: =C30/B30 -> 0.090909091

Sheet Course_State Analysis
A1: Course | B1: Total Leads | C1: Converted Leads | D1: Conversion Rate
A2: General Education Counselling | B2: =COUNTIF(CLEAN_DATA!$D$2:$D$67,A2) -> 29 | C2: =COUNTIFS(CLEAN_DATA!$D$2:$D$67,A2,CLEAN_DATA!$G$2:$G$67,"Converted") -> 2 | D2: =C2/B2 -> 0.068965517
A3: Bed Foundation | B3: =COUNTIF(CLEAN_DATA!$D$2:$D$67,A3) -> 1 | C3: =COUNTIFS(CLEAN_DATA!$D$2:$D$67,A3,CLEAN_DATA!$G$2:$G$67,"Converted") -> 0 | D3: =C3/B3 -> 0 | G3: Top 5 Courses By lead
A4: Bachelor of Public Health | B4: =COUNTIF(CLEAN_DATA!$D$2:$D$67,A4) -> 1 | C4: =COUNTIFS(CLEAN_DATA!$D$2:$D$67,A4,CLEAN_DATA!$G$2:$G$67,"Converted") -> 0 | D4: =C4/B4 -> 0
A5: School Education | B5: =COUNTIF(CLEAN_DATA!$D$2:$D$67,A5) -> 1 | C5: =COUNTIFS(CLEAN_DATA!$D$2:$D$67,A5,CLEAN_DATA!$G$2:$G$67,"Converted") -> 0 | D5: =C5/B5 -> 0 | F5: Rank | G5: Course | H5: Total Leads
A6: Intellectual Property Rights | B6: =COUNTIF(CLEAN_DATA!$D$2:$D$67,A6) -> 1 | C6: =COUNTIFS(CLEAN_DATA!$D$2:$D$67,A6,CLEAN_DATA!$G$2:$G$67,"Converted") -> 0 | D6: =C6/B6 -> 0 | F6: 1 | G6: =INDEX($A$2:$A$21,_xlfn.AGGREGATE(15,6,(ROW($B$2:$B$21)-ROW($B$2)+1)/($B$2:$B$21=H6),COUNTIF($H$5:H5,H6)+1)) -> General Education Counselling | H6: =LARGE($B$2:$B$21,ROWS($H$6:H6)) -> 29
A7: Science / PCMB | B7: =COUNTIF(CLEAN_DATA!$D$2:$D$67,A7) -> 1 | C7: =COUNTIFS(CLEAN_DATA!$D$2:$D$67,A7,CLEAN_DATA!$G$2:$G$67,"Converted") -> 0 | D7: =C7/B7 -> 0 | F7: 2 | G7: =INDEX($A$2:$A$21,_xlfn.AGGREGATE(15,6,(ROW($B$2:$B$21)-ROW($B$2)+1)/($B$2:$B$21=H7),COUNTIF($H$5:H6,H7)+1)) -> Bachelor of Hospital Administration | H7: =LARGE($B$2:$B$21,ROWS($H$6:H7)) -> 7
A8: Sanitary Inspector | B8: =COUNTIF(CLEAN_DATA!$D$2:$D$67,A8) -> 1 | C8: =COUNTIFS(CLEAN_DATA!$D$2:$D$67,A8,CLEAN_DATA!$G$2:$G$67,"Converted") -> 0 | D8: =C8/B8 -> 0 | F8: 3 | G8: =INDEX($A$2:$A$21,_xlfn.AGGREGATE(15,6,(ROW($B$2:$B$21)-ROW($B$2)+1)/($B$2:$B$21=H8),COUNTIF($H$5:H7,H8)+1)) -> Fashion Design | H8: =LARGE($B$2:$B$21,ROWS($H$6:H8)) -> 4
A9: Bachelor of Business Administration | B9: =COUNTIF(CLEAN_DATA!$D$2:$D$67,A9) -> 1 | C9: =COUNTIFS(CLEAN_DATA!$D$2:$D$67,A9,CLEAN_DATA!$G$2:$G$67,"Converted") -> 1 | D9: =C9/B9 -> 1 | F9: 4 | G9: =INDEX($A$2:$A$21,_xlfn.AGGREGATE(15,6,(ROW($B$2:$B$21)-ROW($B$2)+1)/($B$2:$B$21=H9),COUNTIF($H$5:H8,H9)+1)) -> Bachelor of Architecture | H9: =LARGE($B$2:$B$21,ROWS($H$6:H9)) -> 4
A10: Fashion Communication | B10: =COUNTIF(CLEAN_DATA!$D$2:$D$67,A10) -> 1 | C10: =COUNTIFS(CLEAN_DATA!$D$2:$D$67,A10,CLEAN_DATA!$G$2:$G$67,"Converted") -> 0 | D10: =C10/B10 -> 0 | F10: 5 | G10: =INDEX($A$2:$A$21,_xlfn.AGGREGATE(15,6,(ROW($B$2:$B$21)-ROW($B$2)+1)/($B$2:$B$21=H10),COUNTIF($H$5:H9,H10)+1)) -> Bachelor of Design | H10: =LARGE($B$2:$B$21,ROWS($H$6:H10)) -> 3
A11: Fashion Design | B11: =COUNTIF(CLEAN_DATA!$D$2:$D$67,A11) -> 4 | C11: =COUNTIFS(CLEAN_DATA!$D$2:$D$67,A11,CLEAN_DATA!$G$2:$G$67,"Converted") -> 0 | D11: =C11/B11 -> 0
A12: Bachelor of Design | B12: =COUNTIF(CLEAN_DATA!$D$2:$D$67,A12) -> 3 | C12: =COUNTIFS(CLEAN_DATA!$D$2:$D$67,A12,CLEAN_DATA!$G$2:$G$67,"Converted") -> 0 | D12: =C12/B12 -> 0
A13: B.Des Animation Film Design | B13: =COUNTIF(CLEAN_DATA!$D$2:$D$67,A13) -> 1 | C13: =COUNTIFS(CLEAN_DATA!$D$2:$D$67,A13,CLEAN_DATA!$G$2:$G$67,"Converted") -> 1 | D13: =C13/B13 -> 1
A14: B.Des Game Design | B14: =COUNTIF(CLEAN_DATA!$D$2:$D$67,A14) -> 2 | C14: =COUNTIFS(CLEAN_DATA!$D$2:$D$67,A14,CLEAN_DATA!$G$2:$G$67,"Converted") -> 1 | D14: =C14/B14 -> 0.5
A15: Interior Design | B15: =COUNTIF(CLEAN_DATA!$D$2:$D$67,A15) -> 2 | C15: =COUNTIFS(CLEAN_DATA!$D$2:$D$67,A15,CLEAN_DATA!$G$2:$G$67,"Converted") -> 0 | D15: =C15/B15 -> 0
A16: Bachelor of Hospital Administration | B16: =COUNTIF(CLEAN_DATA!$D$2:$D$67,A16) -> 7 | C16: =COUNTIFS(CLEAN_DATA!$D$2:$D$67,A16,CLEAN_DATA!$G$2:$G$67,"Converted") -> 1 | D16: =C16/B16 -> 0.14285714
A17: Animation & VFX | B17: =COUNTIF(CLEAN_DATA!$D$2:$D$67,A17) -> 1 | C17: =COUNTIFS(CLEAN_DATA!$D$2:$D$67,A17,CLEAN_DATA!$G$2:$G$67,"Converted") -> 0 | D17: =C17/B17 -> 0
A18: Bachelor of Visual Arts | B18: =COUNTIF(CLEAN_DATA!$D$2:$D$67,A18) -> 2 | C18: =COUNTIFS(CLEAN_DATA!$D$2:$D$67,A18,CLEAN_DATA!$G$2:$G$67,"Converted") -> 0 | D18: =C18/B18 -> 0
A19: Bachelor of Architecture | B19: =COUNTIF(CLEAN_DATA!$D$2:$D$67,A19) -> 4 | C19: =COUNTIFS(CLEAN_DATA!$D$2:$D$67,A19,CLEAN_DATA!$G$2:$G$67,"Converted") -> 0 | D19: =C19/B19 -> 0
A20: Bachelor of Vocation | B20: =COUNTIF(CLEAN_DATA!$D$2:$D$67,A20) -> 2 | C20: =COUNTIFS(CLEAN_DATA!$D$2:$D$67,A20,CLEAN_DATA!$G$2:$G$67,"Converted") -> 0 | D20: =C20/B20 -> 0
A21: Bachelor of Hotel Management / Culinary Arts | B21: =COUNTIF(CLEAN_DATA!$D$2:$D$67,A21) -> 1 | C21: =COUNTIFS(CLEAN_DATA!$D$2:$D$67,A21,CLEAN_DATA!$G$2:$G$67,"Converted") -> 0 | D21: =C21/B21 -> 0
A22: Total | B22: =SUBTOTAL(109,Table10[Total Leads]) -> 66 | C22: =SUBTOTAL(109,Table10[Converted Leads]) -> 6 | D22: =C22/B22 -> 0.090909091
G24: TOP 5 State By lead
A26: State | B26: Total Leads | C26: Converted Leads | D26: Conversion Rate | F26: Rank | G26: State | H26: Total lead
A27: Rajasthan | B27: =COUNTIF(CLEAN_DATA!$E$2:$E$67,A27) -> 7 | C27: =COUNTIFS(CLEAN_DATA!$E$2:$E$67,A27,CLEAN_DATA!$G$2:$G$67,"Converted") -> 0 | D27: =C27/B27 -> 0 | F27: 1 | G27: =INDEX($A$27:$A$36,_xlfn.AGGREGATE(15,6,(ROW($B$27:$B$36)-ROW($B$27)+1)/($B$27:$B$36=H27),COUNTIF($H$26:H26,H27)+1)) -> Rajasthan | H27: =LARGE($B$27:$B$36,ROWS($H$27:H27)) -> 7
A28: West Bengal | B28: =COUNTIF(CLEAN_DATA!$E$2:$E$67,A28) -> 7 | C28: =COUNTIFS(CLEAN_DATA!$E$2:$E$67,A28,CLEAN_DATA!$G$2:$G$67,"Converted") -> 2 | D28: =C28/B28 -> 0.28571429 | F28: 2 | G28: =INDEX($A$27:$A$36,_xlfn.AGGREGATE(15,6,(ROW($B$27:$B$36)-ROW($B$27)+1)/($B$27:$B$36=H28),COUNTIF($H$26:H27,H28)+1)) -> West Bengal | H28: =LARGE($B$27:$B$36,ROWS($H$27:H28)) -> 7
A29: Telangana | B29: =COUNTIF(CLEAN_DATA!$E$2:$E$67,A29) -> 7 | C29: =COUNTIFS(CLEAN_DATA!$E$2:$E$67,A29,CLEAN_DATA!$G$2:$G$67,"Converted") -> 2 | D29: =C29/B29 -> 0.28571429 | F29: 3 | G29: =INDEX($A$27:$A$36,_xlfn.AGGREGATE(15,6,(ROW($B$27:$B$36)-ROW($B$27)+1)/($B$27:$B$36=H29),COUNTIF($H$26:H28,H29)+1)) -> Telangana | H29: =LARGE($B$27:$B$36,ROWS($H$27:H29)) -> 7
A30: Karnataka | B30: =COUNTIF(CLEAN_DATA!$E$2:$E$67,A30) -> 7 | C30: =COUNTIFS(CLEAN_DATA!$E$2:$E$67,A30,CLEAN_DATA!$G$2:$G$67,"Converted") -> 0 | D30: =C30/B30 -> 0 | F30: 4 | G30: =INDEX($A$27:$A$36,_xlfn.AGGREGATE(15,6,(ROW($B$27:$B$36)-ROW($B$27)+1)/($B$27:$B$36=H30),COUNTIF($H$26:H29,H30)+1)) -> Karnataka | H30: =LARGE($B$27:$B$36,ROWS($H$27:H30)) -> 7
A31: Odisha | B31: =COUNTIF(CLEAN_DATA!$E$2:$E$67,A31) -> 7 | C31: =COUNTIFS(CLEAN_DATA!$E$2:$E$67,A31,CLEAN_DATA!$G$2:$G$67,"Converted") -> 0 | D31: =C31/B31 -> 0 | F31: 5 | G31: =INDEX($A$27:$A$36,_xlfn.AGGREGATE(15,6,(ROW($B$27:$B$36)-ROW($B$27)+1)/($B$27:$B$36=H31),COUNTIF($H$26:H30,H31)+1)) -> Odisha | H31: =LARGE($B$27:$B$36,ROWS($H$27:H31)) -> 7
A32: Kerala | B32: =COUNTIF(CLEAN_DATA!$E$2:$E$67,A32) -> 6 | C32: =COUNTIFS(CLEAN_DATA!$E$2:$E$67,A32,CLEAN_DATA!$G$2:$G$67,"Converted") -> 0 | D32: =C32/B32 -> 0
A33: Delhi | B33: =COUNTIF(CLEAN_DATA!$E$2:$E$67,A33) -> 6 | C33: =COUNTIFS(CLEAN_DATA!$E$2:$E$67,A33,CLEAN_DATA!$G$2:$G$67,"Converted") -> 0 | D33: =C33/B33 -> 0 | F33: Note: Six states are tied at 7 leads. The first five are shown based on their order in the State-wise table.
A34: Maharashtra | B34: =COUNTIF(CLEAN_DATA!$E$2:$E$67,A34) -> 6 | C34: =COUNTIFS(CLEAN_DATA!$E$2:$E$67,A34,CLEAN_DATA!$G$2:$G$67,"Converted") -> 1 | D34: =C34/B34 -> 0.16666667
A35: Tamil Nadu | B35: =COUNTIF(CLEAN_DATA!$E$2:$E$67,A35) -> 6 | C35: =COUNTIFS(CLEAN_DATA!$E$2:$E$67,A35,CLEAN_DATA!$G$2:$G$67,"Converted") -> 0 | D35: =C35/B35 -> 0
A36: Andhra Pradesh | B36: =COUNTIF(CLEAN_DATA!$E$2:$E$67,A36) -> 7 | C36: =COUNTIFS(CLEAN_DATA!$E$2:$E$67,A36,CLEAN_DATA!$G$2:$G$67,"Converted") -> 1 | D36: =C36/B36 -> 0.14285714
A37: Total | B37: =SUBTOTAL(109,Table11[Total Leads]) -> 66 | C37: =SUBTOTAL(109,Table11[Converted Leads]) -> 6 | D37: =C37/B37 -> 0.090909091

Sheet Assumptions & Methodology
A1: Section | B1: Details
A2: Data Cleaning | B2: Course names were standardized by removing unnecessary spaces. State/Country, Counsellor Name, Lead Status, Chat/Call Status, and Lead Source were validated.
A3: Data Quality Review | B3: Records with potentially placeholder/unclear student names such as Hdhdbhd, Anonymous, Test, and sdfgsdfg were flagged for review instead of being deleted.
A4: Duplicate Identification | B4: Duplicate records were identified using Student Name only, as specified in the task.
A5: Duplicate Handling | B5: 30 duplicate records were identified. Duplicate records were flagged but not removed. All analysis was performed on the complete 66-record dataset.
A6: Lead Status Analysis | B6: Lead Status was analyzed using the categories New, Follow-up, Pending, Converted, and Not Interested.
A7: Chat/Call Analysis | B7: The analysis uses the actual Chat/Call Status categories available in the dataset rather than inventing the example categories mentioned in the task sheet.
A8: Follow-up Definition | B8: A lead was marked as requiring follow-up when Lead Status was Follow-up, or the Chat/Call Status indicated Call back tomorrow or Interested - follow up.
A9: Conversion Rate | B9: Conversion Rate = Converted Leads ÷ Total Leads × 100.
A10: Top 5 Analysis | B10: Top 5 courses and states were ranked based on lead volume, not conversion rate.
A11: Tie Handling | B11: Where lead volumes were tied, the order of the existing analysis table was used. Six states had 7 leads; the first five were displayed in the Top 5 section and the tie was documented.
A12: Dashboard | B12: The dashboard summarizes key KPIs, counsellor performance, lead status, lead sources, top courses, top states, conversion rates, and key observations.
... A14: Key Analytical Principles | B14: The analysis was performed on the complete dataset without removing duplicate records. Duplicate identification was treated as a data-quality exercise. Calculations and insights were based on the available data, and unclear records were flagged for review rather than making unsupported assumptions.

Sheet Dashboard
A1: Lead & Counsellor Analysis Dashboard
A4: Total Leads | C4: ='Conversion Analysis'!B2 -> 66 | E4: Converted Leads | G4: ='Conversion Analysis'!B3 -> 6 | I4: Conversion Rate | K4: ='Conversion Analysis'!B4 -> 0.090909091 | M4: Best Counsellor | O4: ='Counsellor Analysis'!D10 -> Anjali | Q4: Follow-up Required | T4: =COUNTIF(CLEAN_DATA!$M$2:$M$67,"Yes") -> 27
A37: Key Insights & Observations
B40: Overall Conversion: 6 out of 66 leads were converted, resulting in an overall conversion rate of 9.09%.
B42: Best Counsellor: Anjali has the highest conversion rate at 12.50%, with 2 conversions from 16 leads.
B44: Top Course: General Education Counselling generated the highest lead volume with 29 leads.
B46: Best Lead Sources: Facebook and Instagram have the highest conversion rate at 15.38% each.
B48: Website Opportunity: Website generated 13 leads but 0 conversions, suggesting that this source may need further investigation.
B50: State Performance: West Bengal and Telangana recorded the highest conversion rate at 28.57%, with 2 conversions from 7 leads each.
